Workbook

Sheet Cover
A1: Europe Private Debt & Alternative Credit Investors - Relevance to the CPEF I Curity and Impactus Pyrolysis (IPL) raises
A2: Impactus Private Equity Group - internal working workbook - prepared 22 September 2026 - source article: Cascade Debt, 'Private Debt and Alternative Credit Investors in Europe' (2026 Europe Private ABF Investor Market Map)
A4: Purpose | B4: Map the European private debt / alternative credit investor universe (Cascade 2026 ABF map plus the wider direct lending, special situations, infrastructure credit, venture debt, impact and DFI universe), score each firm for relevance to the IPL (€5m equity + €35m venture debt + senior refinancing optionality) and CPEF (8% note today; €3m to €10m growth facility next) raises, and give a named, channel-specific contact plan.
A5: How to read the tabs | B5: 1 Exec_Summary: headline counts and capacity. 2 Market_Overview: sourced market data. 3 Segment_Map: which credit segment fits which Impactus need. 4 Cascade_Map_2026: the article's investor map transcribed and scored. 5 Investor_Universe: scored target list (firm level). 6 Contacts: named decision-makers with channel recommendation. 7 Existing_Pipeline: warm relationships already in Impactus records. 8 IPL_Debt_Capacity and 9 CPEF_Debt_Capacity: live models. 10 Outreach_Plan and 11 Conferences. 12 Scoring_Weights: change weights here. 13 Sources.
A6: Colour legend | B6: Blue text on yellow = input you can change. Black = formula or fixed data. Green = link to another tab. Scores recalculate when weights on Scoring_Weights change.
A7: Data status | B7: External figures are sourced (see Sources tab, URL per row). Contact emails: only those published on public pages are shown as 'published'; 'pattern - unverified' means the firm's public address format, to be verified before sending. LinkedIn URLs are public profile URLs found in September 2026. Apollo.io enrichment was not available in this session (free plan blocks API search and enrichment), so no purchased data is included.
A8: Analytical stance | B8: Bear case first. Rows flagged 'DD challenge' name the objection an LP due-diligence lead, lender credit committee or CySEC reviewer would raise. The memo (Word) carries the argued position; this workbook carries the evidence and the working models.
A9: Disclaimer | B9: AIFMD Art. 23 disclosure: Impactus RAIF V.C.I.C. Plc is a Registered Alternative Investment Fund (CySEC RAIF16) externally managed by Argus Management Ltd (CySEC AIFM 44/56/2013). This workbook is an internal working document prepared for the Sponsor and is not an offer, solicitation or marketing communication. Interests in the Fund and its sub-funds (Impactus Private Equity Fund, CPEF I Curity, Impactus Pyrolysis / IVP) are available only to professional and well-informed investors within the meaning of AIFMD Art. 4(1)(ag), MiFID II and the Cyprus AIF Law 124(I)/2018. Prospective investors must read the AIFMD Art. 23 disclosure document, the relevant offering supplement and term sheet before investing. Targets are gross, forward-looking and not guaranteed; capital is at risk. Third-party names are used for identification only and do not imply endorsement.

Sheet Exec_Summary
A1: Executive summary - the numbers behind the memo
A2: All counts are live formulas over the scored tabs
A4: Measure | B4: Value | C4: Read-across
A5: Firms scored in the wider universe (Investor_Universe) | B5: =COUNTA(Investor_Universe!A5:A82) | C5: Direct lending, special situations, infrastructure credit, venture debt, impact, DFI, cannabis credit, placement, fund finance
A6: Firms on the Cascade 2026 Europe ABF map (Cascade_Map_2026) | B6: =COUNTA(Cascade_Map_2026!A5:A114) | C6: The article's universe, transcribed and scored
A7: Tier 1 targets - wider universe | B7: =COUNTIF(Investor_Universe!S5:S82,"Tier 1") | C7: Approach in Wave 1 (weeks 1-4)
A8: Tier 1 targets - Cascade map | B8: =COUNTIF(Cascade_Map_2026!S5:S114,"Tier 1") | C8: ABF investors that could still do a single hard asset or a receivables/inventory line
A9: Tier 2 targets - both tabs | B9: =COUNTIF(Investor_Universe!S5:S82,"Tier 2")+COUNTIF(Cascade_Map_2026!S5:S114,"Tier 2") | C9: Wave 2 (weeks 5-10)
A10: Named contacts with a warm path | B10: =COUNTIF(Contacts!I5:I72,"<>") | C10: Use first
A11: Named contacts with a published email | B11: =COUNTIF(Contacts!H5:H72,"published") | C11: Email + LinkedIn note same day
A12: Named contacts with LinkedIn only | B12: =COUNTIFS(Contacts!F5:F72,"<>not found",Contacts!H5:H72,"<>published") | C12: LinkedIn first
A13: Total named contacts | B13: =COUNTA(Contacts!B5:B72)
A14: IPL: senior debt capacity on model CFADS at 1.5x DSCR (€m) | B14: =IPL_Debt_Capacity!E16 | C14: vs €77.4m in the Sponsor plan
A15: IPL: senior debt capacity at contracted gate fee (€62/t on 11ktpa ~ €15/t on 45ktpa), €1,500/t rCB (€m) | B15: =PV(IPL_Debt_Capacity!B19,IPL_Debt_Capacity!B20,-(((IPL_Debt_Capacity!B5*IPL_Debt_Capacity!B6*IPL_Debt_Capacity!B7+IPL_Debt_Capacity!B5*IPL_Debt_Capacity!B8*IPL_Debt_Capacity!B9+IPL_Debt_Capacity!B5*IPL_Debt_Capacity!B10*IPL_Debt_Capacity!B11+IPL_Debt_Capacity!B5*15+IPL_Debt_Capacity!B5*IPL_Debt_Capacity!B13)/1000000-IPL_Debt_Capacity!E11)*(1-IPL_Debt_Capacity!B16)-IPL_Debt_Capacity!B5*IPL_Debt_Capacity!B15/1000000)/IPL_Debt_Capacity!B21) | C15: What a credit committee sizes on today
A16: IPL: funding gap vs plan if capex stress applies (€m) | B16: =IPL_Debt_Capacity!E26 | C16: Negative = shortfall to be filled by private credit or equity
A17: IPL: venture-debt all-in cost | B17: =IPL_Debt_Capacity!E20 | C17: 4% cash + 5% PIK + warrants
A18: IPL: blended cost of capital | B18: =IPL_Debt_Capacity!E29
A19: CPEF: growth-facility headroom at stressed plan (€m) | B19: =CPEF_Debt_Capacity!E8 | C19: At 2.5x leverage on €3.00/g stressed EBITDA
A20: CPEF: all-in cost of a specialist growth facility | B20: =CPEF_Debt_Capacity!E14 | C20: vs 8% note

Sheet Market_Overview
A1: European private debt and alternative credit - market data (sourced)
A2: Figures as published; where sources conflict both are shown. See Sources tab for URLs.
A4: Metric | B4: Value | C4: Unit | D4: Period | E4: Source | F4: Relevance to Impactus raise
A5: European private credit AUM | B5: c.€400b (other estimate US$340b) | C5: €b | D5: 2026 | E5: AllianzGI / Revelle Capital; ctacquisitions (cites Preqin) | F5: The pool is large; the constraint for Impactus is fit, not supply
A6: Global private credit AUM | B6: c.US$1.7t (broader definitions >US$2.5t) | C6: US$t | D6: 2025-26 | E6: Preqin 2025 global report; ctacquisitions | F6: Context only
A7: Europe private debt fundraising FY2025 | B7: US$79.4b (PitchBook); US$69.9b (S&P / With Intelligence) | C7: US$b | D7: FY2025 | E7: PitchBook; S&P press release | F7: Second-highest year ever; +29% to +40% YoY depending on source
A8: Europe share of global private credit fundraising | B8: 23% (2024) to 46% (2025) | C8: % | D8: 2025 | E8: Alternative Credit Investor 16-12-2025; PitchBook | F8: Capital is rotating to Europe - the window for European stories is open
A9: Direct lending share of European capital raised | B9: 61.5% | C9: % | D9: 9M 2025 | E9: Alternative Credit Investor 16-12-2025 (Preqin) | F9: Most of the money is corporate sponsor-backed lending - not IPL or CPEF's segment
A10: Concentration of fundraising | B10: 93.1% of global private debt capital to managers on Fund IV or later | C10: % | D10: 2025 | E10: PitchBook 2025 Annual Global Private Debt Report | F10: LPs back scale; a first-time sub-€100m GP will not raise from these allocators directly
A11: European direct lending deal volume Q2 2026 | B11: €28.4b / 296 deals (Q2 2025: €38.0b / 367); Q1 2026 €34.8b / 303 | C11: €b | D11: Q2 2026 | E11: Alternative Credit Investor 25-08-2026 | F11: Deal flow slowing; lenders have dry powder and are competing for assets
A12: Deloitte Private Debt Deal Tracker H1 2025 | B12: 421 deals; avg deal size €204.9m; 89 lenders | C12: count | D12: H1 2025 | E12: Deloitte UK Private Debt Deal Tracker (Autumn 2025) | F12: Average ticket is 5x to 40x Impactus' need - target the lower-mid and specialist tail
A13: Unitranche pricing, European mid-market | B13: Euribor + 525 to 625bps (traditional mid-market); +500 to 600bps (upper) | C13: bps | D13: Q1-Q2 2026 | E13: Valuation Research Corp Q2 2026 European update | F13: Benchmark for what 'senior' costs a sponsor-backed corporate; IPL is not that credit
A14: Mezzanine / junior yields | B14: 13% to 16% all-in; spreads 450 to 1,300bps by seniority | C14: % | D14: 2026 | E14: ddtalks (secondary source - verify) | F14: The €35m venture-debt tranche at 10% blended is priced below where junior capital clears for a FOAK asset
A15: Special situations fundraising | B15: H1 2026: Alchemy, Metric Capital, Tikehau each closed €1b+ funds; European pipeline c.£100b | C15: €b | D15: H1 2026 | E15: With Intelligence emerging managers 2026; Alternative Credit Investor 19-02-2026 | F15: Special-sits desks have the mandate for hybrid, PIK and warrants that IPL needs
... A28: Specialist cannabis lenders (US) | B28: Chicago Atlantic REFI: US$453m, 26 borrowers, 15.8% weighted YTM; AFC Gamma: US$290m, 13.2% yield, 35.7% non-accrual | C28: US$m | D28: 30-06-2026 | E28: REFI / AFCG 10-Q via research briefing | F28: No European loan on record for any specialist cannabis lender; pricing anchor 13% to 16%

Sheet Segment_Map
A1: Segment map - which part of the credit market fits which Impactus need
A2: Fit scores 0-5 are analyst judgement (basis stated); pricing ranges are market-observed 2025-2026
A4: Segment | B4: Europe size / activity | C4: Typical pricing | D4: Typical ticket | E4: Instruments / hold | F4: IPL fit (0-5) | G4: CPEF fit (0-5) | H4: Why / basis | I4: Representative firms
A5: Asset-based finance (ABF) - the Cascade map universe | B5: Global ABF c.US$6.1t (2025) to c.US$9t by 2029 (Apollo); Europe: warehouse lines to originators, forward-flow, portfolio purchases, specialty-finance equity | C5: Senior warehouse E+300 to 600bps; advance rates 65% to 85%; mezz 10% to 15% | D5: €25m to €500m per facility | E5: Revolving warehouse, forward-flow, portfolio acquisition, real-asset ABL; 2 to 5 years | F5: 1 | G5: 2 | H5: ABF investors lend against granular pools with observable performance data. A single FOAK plant is not a pool. Curity could in time support a small inventory / receivables line once German distribution creates receivables - but no European ABF investor has a cannabis precedent. Only the special-situations and real-asset ABL sub-set of the map (Fortress, Davidson Kempner, Castlelake, Arrow, Pollen Street, Kartesia, Incus, Chenavari, Sixth Street, Apollo) could stretch to a single hard asset. | I5: Fortress, Davidson Kempner, Castlelake, Waterfall, Arrow Global, Pollen Street, Kartesia, Incus Capital, Chenavari, Sixth Street
A6: Sponsor-backed direct lending (senior / unitranche) | B6: 61.5% of European capital raised 9M 2025; H1 2026 volume c.€63b | C6: E+500 to 625bps unitranche; 5.0x to 6.5x EBITDA | D6: €30m to €500m | E6: Unitranche / senior term loans; 5 to 7 years; corporate borrowers with EBITDA | F6: 0 | G6: 1 | H6: Requires positive, audited EBITDA and usually a PE sponsor. IPL has no EBITDA until 2029; Curity has EBITDA below €2m today. Exclude from Wave 1. | I6: Ares, Arcmont, Hayfin, Pemberton, Tikehau, Bridgepoint Credit, Eurazeo, CVC Credit, ICG
A7: Lower-mid-market / SME credit (Southern Europe) | B7: Kartesia KCO VI €1.3b; Capza PD 7 c.€1.4b first close; Beechbrook €2m to €25m bites; Greek AIFs (Elikonos 3 €175m) | C7: 9% to 14% all-in; often with PIK and warrants | D7: €3m to €30m | E7: Senior, unitranche, hybrid; 3 to 6 years | F7: 2 | G7: 3 | H7: The only segment of the core direct-lending market that writes Impactus-sized tickets. Kartesia and Capza have Southern Europe teams; Elikonos / Halcyon are Greek and EIF-backed (state-aid sensitive on cannabis). Fit for a Curity growth facility once revenue is audited; for IPL only as holdco / sponsor-level hybrid. | I7: Kartesia, Capza, Muzinich, Beechbrook, Cordet, Elikonos, Halcyon, Waterwheel, Azimut Direct
A8: Special situations / opportunistic credit | B8: Alchemy, Metric, Tikehau €1b+ funds closed H1 2026; UK / Europe pipeline c.£100b | C8: 12% to 20% IRR targets; PIK, warrants, control rights | D8: €10m to €150m | E8: Bespoke senior / junior, PIK toggles, equity kickers; 3 to 5 years | F8: 4 | G8: 2 | H8: This is the natural home of a €35m FOAK tranche at 10% cash + PIK + warrants. The price will be higher than 10% blended (expect 14% to 18% all-in with 10% to 20% warrant coverage). Cannabis: case by case, most decline on reputational grounds. | I8: Hayfin Special Opportunities, Blantyre, Cheyne Strategic Value Credit, Davidson Kempner, Fortress, Arini, Chenavari, Incus, Fasanara, Pollen Street
A9: Infrastructure and energy-transition debt | B9: Record £68b European infra debt 2025; Infranity €3.2b (2025); Eiffel EET III €1.2b; Rivage REDI HR3 €700m target; CIP Green Credit II €1.3b first close | C9: Senior IG-like: E+150 to 250bps; enhanced-return / sub-IG: 7% to 10% | D9: €20m to €150m | E9: Senior secured project debt, construction-plus-operations; 7 to 20 years | F9: 3 | G9: 0 | H9: Infra-debt funds want contracted cash flows, an EPC wrap and a technology with references. Thermo Lysi has the grant, an EPC under negotiation and a TRL 8-9 process, but no lender-grade offtake yet. Enhanced-return sleeves (Infranity ERDF, Rivage High Yield, Eiffel bridge vs grant receivable) are the realistic entry. No European infra-debt fund has financed a tyre-pyrolysis plant to date. | I9: Infranity (Enhanced Return), Rivage (REDI HR / European Climate Debt Solutions), Eiffel Energy Transition, Polestar Capital, Aquila, Edmond de Rothschild BRIDGE, AXA IM Alts, AllianzGI
A10: Venture debt / growth debt | B10: Kreos/BlackRock >US$7b committed, 830+ deals; Claret IV €575m; Atempo II >€455m | C10: 10% to 13% cash + 5% to 15% warrant coverage | D10: €5m to €40m | E10: 3 to 4 year amortising term loans; VC-backed revenue companies | F10: 2 | G10: 3 | H10: Structurally the closest instrument to the VD tranche, but growth-debt lenders underwrite VC-backed recurring revenue, not construction. Kreos' Aris Constantinides (Greek) is a warm angle. For Curity, growth debt becomes available once 12 months of audited German sales exist; no cannabis exclusion located for Kreos, Claret or Atempo. | I10: Kreos Capital, Claret Capital, Atempo Growth, Columbia Lake, Bootstrap Europe, Flashpoint, Harbert
A11: Development finance and public co-financing | B11: EIB Group Greece €3.5b (2025); EIB venture debt (Joltie €17.5m); EIF InvestEU guarantees; HDB Green Co-Financing; EU Innovation Fund IF25 (€2.9b, results Oct-Nov 2026) | C11: EIB VD: quasi-equity, cash + PIK + warrants c.8% to 12%; HDB: 40% interest-free | D11: €5m to €50m | E11: Venture debt, guarantees, co-financed bank loans | F11: 4 | G11: 1 | H11: EIB Cleantech declined in April 2026 ('mezzanine risk without equity reward') and re-engaged in September via Sirec - the reopened process is the single most valuable live thread. EBRD Greece closed for new deals Dec 2025. HDB / RRF windows closed Aug 2026. Cannabis: no formal exclusion at EIB / EBRD but no precedent. | I11: EIB Cleantech Equity & Growth Capital, EIF InvestEU, HDB, HDBI, Growthfund / HCAP
A12: Impact and climate credit funds | B12: Blue Earth climate strategy US$378m; Rivage European Climate Debt Solutions (EIF-backed); Triodos Energy Transition; Polestar (Xycle senior debt) | C12: 8% to 12% senior impact debt; blended finance structures | D12: €5m to €30m | E12: Senior / mezz impact loans; 5 to 10 years | F12: 4 | G12: 0 | H12: Best mandate fit for IPL: 784,304 tCO2e avoided, EU Innovation Fund validation, STEP seal. Polestar Capital is the only European impact lender with a chemical-recycling senior loan (Xycle). Cannabis excluded by most impact mandates. | I12: Polestar Capital, Rivage ECDS, Blue Earth Capital, Triodos IM, Mirova, SUSI Partners, Climate Fund Managers
A13: Strategic / offtaker capital | B13: BASF €16m + €25m conditional loan into Pyrum; bp €12.5m debt + 8-year offtake to Circtec; Continental 10-year rCB framework; Pirelli / BASF / Synthos tyre-to-tyre | C13: Below-market coupon in exchange for offtake / supply rights | D13: €5m to €25m | E13: Prepayment, offtaker loan, equity | F13: 5 | G13: 3 | H13: The pattern across every financed European pyrolysis project is grant + strategic equity + offtaker-linked debt, not fund debt. For IPL the highest-probability €10m to €15m is an offtaker prepayment or loan (BASF for oil, Continental / Pirelli via Pyrum for rCB, Archirodon deferred EPC payment). For Curity, ELPEN and German importers (Cantourage, Cansativa, Curaleaf International) are the equivalent. | I13: BASF, Continental, Pirelli, Pyrum, Archirodon, VTTI, Vitol; ELPEN, Cantourage, Cansativa, Curaleaf International, Galenica
A14: Specialist cannabis credit | B14: Chicago Atlantic REFI US$453m at 15.8% YTM; AFC Gamma US$290m at 13.2%; Artemis Growth Partners Fund VII US$200m target, c.75% Europe (equity / hybrid) | C14: 13% to 16% senior secured; 10% + equity kicker for European convertibles (Organigram / Sanity 2024) | D14: US$5m to US$50m | E14: Senior secured term loans, convertibles, sale-leasebacks | F14: 0 | G14: 4 | H14: No specialist lender has a documented European loan; Chicago Atlantic (co-founded by John Mazarakis, Greek-American) is the one to test. Artemis is the only fund with a stated European allocation. Expect 13% to 16% and hard-asset security. | I14: Chicago Atlantic, Advanced Flower Capital (AFC Gamma), Artemis Growth Partners, Pelorus (US only), Casa Verde (equity)
A15: Fund finance (capital-call / NAV) | B15: >US$1t market; NAV 28% of European deals; average facility US$285m; banks 88% of new deals | C15: Sub-line E+200 to 300bps; NAV E+500 to 800bps | D15: US$50m minimum for institutional lenders; €5m to €25m from Cyprus / UK boutique banks | E15: Revolving, 1 to 3 years | F15: 1 | G15: 0 | H15: Every institutional NAV lender is above Impactus' scale and every UK lender applies POCA screening to cannabis. Only Eurobank Cyprus (depositary) or Bank of Cyprus could write a small capital-call line for the PE Fund; CPEF must be excluded from any borrowing base. | I15: Eurobank Cyprus, Bank of Cyprus, HSBC Innovation Banking, Investec Fund Solutions, Hark Capital
A16: Placement agents and capital advisors | B16: Success fees 2% to 3% for sub-US$100m funds; retainers US$25k to US$150k; bank-owned groups start at €300m+ | C16: n/a | D16: n/a | E16: Advisory | F16: 2 | G16: 1 | H16: Only Threadmark, Elm, Quest, Cebile, Acanthus and the Greek / Cypriot boutiques (Axia, Ambrosia, Emergo, MeritKapital, Argus) take sub-€150m niche mandates. Every bank-owned PCA excludes cannabis by policy. Impactus already has Venero (debt), KPMG Cyprus (IVP) and Argus (distribution) - add one credit-specialist boutique for the VD tranche, on success fee only. | I16: Threadmark, Elm Capital, Quest Fund Placement, Cebile Capital, Acanthus, Axia Ventures, Ambrosia Capital, Venero (engaged), KPMG Cyprus (engaged)
A17: Cyprus and Greek institutional / family capital | B17: Cyprus provident funds (ETYK, PEO, Cyta, EAC, PASYDY, Doctors', Lawyers', SEK); Greek TEAs (30% alternatives cap); Greek insurers (Ethniki, NN, Generali, Allianz, Interamerican, Eurolife); Growthfund c.€6b; Greek family offices (Latsis, Laskaridis, Martinos, Vardinogiannis backed Greek PE / VC vehicles) | C17: 8% coupon products; equity | D17: €150k to €2m per provident fund; €0.5m to €5m family offices | E17: Fund units, notes, direct co-investment | F17: 3 | G17: 3 | H17: This is where Impactus has actually raised money (SEK, Doctors' Fund, CSE fund, AstroBank, Rodopoulos, Sirec). Scaling it means (a) a note the provident funds can hold under IORP prudent-person rules, (b) Muhanna / Argus as gateways, (c) two or three Greek family offices with VC / PE history as anchors for IVP. | I17: Argus Management, Muhanna & Co, Athlos Capital, Alpha Bank Wealth (Greece), J. Safra Sarasin, KPMG Cyprus

Sheet Cascade_Map_2026
A1: Cascade Map 2026
A2: The article's map transcribed: Cascade Debt 'Private ABF Investor Market Map 2026 - Region: Europe', classified by each firm's dedicated ABL/ABF and private credit strategy. Scores are analyst judgement on public evidence.
A4: Firm | B4: Category | C4: HQ / EU office | D4: Strategy / vehicle | E4: Fund size / AUM | F4: Ticket range | G4: Instruments | H4: Greece / Cyprus / S. Europe evidence | I4: Hard-asset / FOAK evidence | J4: Cannabis stance | K4: S1 IPL fit | L4: S2 CPEF fit | M4: S3 Ticket | N4: S4 Geography | O4: S5 Risk appetite | P4: S6 Warm path | Q4: S7 Speed | R4: Weighted score | S4: Tier | T4: Best use for Impactus | U4: Recommended channel | V4: Warm path via | W4: Source URL
A5: Octopus (Octopus Investments / Real Estate) | B5: Cascade map - AUM < US$5b | C5: London | D5: Specialist lending, real estate and energy [K] | E5: n/a | F5: €5m to €50m | G5: Real-asset lending, energy | H5: UK | I5: Octopus Energy Generation invests in renewables; no pyrolysis | J5: Unknown | K5: 2 | L5: 0 | M5: 4 | N5: 1 | O5: 3 | P5: 1 | Q5: 3 | R5: =ROUND(SUMPRODUCT(K5:Q5,Scoring_Weights!$E$5:$K$5)/Scoring_Weights!$B$12*20,0) | S5: =IF(R5>=Scoring_Weights!$B$15,"Tier 1",IF(R5>=Scoring_Weights!$B$16,"Tier 2","Tier 3")) | T5: Wave 2 - energy / real-asset lending | U5: Cold | W5: Cascade map
A6: Clerville Investment Management | B6: Cascade map - AUM < US$5b | C6: London | D6: Specialty finance credit [K] | E6: n/a | F6: €5m to €30m | G6: ABF | H6: UK / Europe | I6: No | J6: Unknown | K6: 1 | L6: 1 | M6: 4 | N6: 1 | O6: 2 | P6: 1 | Q6: 3 | R6: =ROUND(SUMPRODUCT(K6:Q6,Scoring_Weights!$E$5:$K$5)/Scoring_Weights!$B$12*20,0) | S6: =IF(R6>=Scoring_Weights!$B$15,"Tier 1",IF(R6>=Scoring_Weights!$B$16,"Tier 2","Tier 3")) | T6: Tier 3 | U6: Cold | W6: Cascade map
A7: Invictus Capital Partners | B7: Cascade map - AUM < US$5b | C7: Washington DC | D7: Residential / consumer ABF [K] | E7: n/a | F7: US$10m+ | G7: ABF | H7: US | I7: No | J7: Unknown | K7: 0 | L7: 0 | M7: 3 | N7: 0 | O7: 2 | P7: 1 | Q7: 2 | R7: =ROUND(SUMPRODUCT(K7:Q7,Scoring_Weights!$E$5:$K$5)/Scoring_Weights!$B$12*20,0) | S7: =IF(R7>=Scoring_Weights!$B$15,"Tier 1",IF(R7>=Scoring_Weights!$B$16,"Tier 2","Tier 3")) | T7: Not relevant | U7: n/a | W7: Cascade map
A8: Kirkoswald Asset Management | B8: Cascade map - AUM < US$5b | C8: London | D8: Macro / credit hedge fund [K] | E8: n/a | F8: n/a | G8: Credit | H8: UK | I8: No | J8: Unknown | K8: 0 | L8: 0 | M8: 2 | N8: 0 | O8: 2 | P8: 1 | Q8: 2 | R8: =ROUND(SUMPRODUCT(K8:Q8,Scoring_Weights!$E$5:$K$5)/Scoring_Weights!$B$12*20,0) | S8: =IF(R8>=Scoring_Weights!$B$15,"Tier 1",IF(R8>=Scoring_Weights!$B$16,"Tier 2","Tier 3")) | T8: Not relevant | U8: n/a | W8: Cascade map
A9: Kartesia | B9: Cascade map - AUM < US$5b | C9: Luxembourg | D9: Lower-mid-market credit; KCO VI €1.3b | E9: €1.3b | F9: €10m to €60m | G9: Senior, hybrid, PIK | H9: Southern Europe team | I9: Sponsorless SMEs | J9: Unknown | K9: 3 | L9: 2 | M9: 4 | N9: 3 | O9: 3 | P9: 1 | Q9: 3 | R9: =ROUND(SUMPRODUCT(K9:Q9,Scoring_Weights!$E$5:$K$5)/Scoring_Weights!$B$12*20,0) | S9: =IF(R9>=Scoring_Weights!$B$15,"Tier 1",IF(R9>=Scoring_Weights!$B$16,"Tier 2","Tier 3")) | T9: Holdco hybrid at FID; Curity later | U9: LinkedIn first | W9: kartesia.com
A10: Highlake Capital | B10: Cascade map - AUM < US$5b | C10: London | D10: Specialty finance / ABF [K] | E10: n/a | F10: €5m to €30m | G10: ABF | H10: UK / Europe | I10: No | J10: Unknown | K10: 1 | L10: 1 | M10: 4 | N10: 1 | O10: 2 | P10: 1 | Q10: 3 | R10: =ROUND(SUMPRODUCT(K10:Q10,Scoring_Weights!$E$5:$K$5)/Scoring_Weights!$B$12*20,0) | S10: =IF(R10>=Scoring_Weights!$B$15,"Tier 1",IF(R10>=Scoring_Weights!$B$16,"Tier 2","Tier 3")) | T10: Tier 3 | U10: Cold | W10: Cascade map
A11: Varadero Capital | B11: Cascade map - AUM < US$5b | C11: New York | D11: Structured credit / ABF | E11: n/a | F11: US$10m+ | G11: ABF | H11: US | I11: No | J11: Unknown | K11: 0 | L11: 0 | M11: 3 | N11: 0 | O11: 2 | P11: 1 | Q11: 2 | R11: =ROUND(SUMPRODUCT(K11:Q11,Scoring_Weights!$E$5:$K$5)/Scoring_Weights!$B$12*20,0) | S11: =IF(R11>=Scoring_Weights!$B$15,"Tier 1",IF(R11>=Scoring_Weights!$B$16,"Tier 2","Tier 3")) | T11: Not relevant | U11: n/a | W11: Cascade map
A12: Chorus Capital | B12: Cascade map - AUM < US$5b | C12: London | D12: Bank significant-risk-transfer (SRT) investor | E12: n/a | F12: €20m+ | G12: SRT | H12: Europe | I12: No | J12: Unknown | K12: 0 | L12: 0 | M12: 2 | N12: 1 | O12: 2 | P12: 1 | Q12: 2 | R12: =ROUND(SUMPRODUCT(K12:Q12,Scoring_Weights!$E$5:$K$5)/Scoring_Weights!$B$12*20,0) | S12: =IF(R12>=Scoring_Weights!$B$15,"Tier 1",IF(R12>=Scoring_Weights!$B$16,"Tier 2","Tier 3")) | T12: Not relevant | U12: n/a | W12: Cascade map
A13: Serone Capital Management | B13: Cascade map - AUM < US$5b | C13: London | D13: European structured / ABS credit | E13: n/a | F13: €10m+ | G13: ABS | H13: Europe | I13: No | J13: Unknown | K13: 0 | L13: 0 | M13: 3 | N13: 1 | O13: 2 | P13: 1 | Q13: 2 | R13: =ROUND(SUMPRODUCT(K13:Q13,Scoring_Weights!$E$5:$K$5)/Scoring_Weights!$B$12*20,0) | S13: =IF(R13>=Scoring_Weights!$B$15,"Tier 1",IF(R13>=Scoring_Weights!$B$16,"Tier 2","Tier 3")) | T13: Not relevant | U13: n/a | W13: Cascade map
A14: SPF Investment Management | B14: Cascade map - AUM < US$5b | C14: London | D14: Specialty finance credit | E14: n/a | F14: €5m to €30m | G14: ABF | H14: Europe | I14: No | J14: Unknown | K14: 1 | L14: 1 | M14: 4 | N14: 1 | O14: 2 | P14: 1 | Q14: 3 | R14: =ROUND(SUMPRODUCT(K14:Q14,Scoring_Weights!$E$5:$K$5)/Scoring_Weights!$B$12*20,0) | S14: =IF(R14>=Scoring_Weights!$B$15,"Tier 1",IF(R14>=Scoring_Weights!$B$16,"Tier 2","Tier 3")) | T14: Tier 3 | U14: Cold | W14: Cascade map
A15: Viola Credit | B15: Cascade map - AUM < US$5b | C15: Tel Aviv / London | D15: Venture lending and ABF to fintech / tech companies | E15: n/a | F15: US$5m to US$50m | G15: Venture debt, warehouse | H15: Israel / Europe | I15: Tech lending; Israel cannabis-tolerant ecosystem | J15: Unknown | K15: 1 | L15: 2 | M15: 5 | N15: 2 | O15: 3 | P15: 1 | Q15: 4 | R15: =ROUND(SUMPRODUCT(K15:Q15,Scoring_Weights!$E$5:$K$5)/Scoring_Weights!$B$12*20,0) | S15: =IF(R15>=Scoring_Weights!$B$15,"Tier 1",IF(R15>=Scoring_Weights!$B$16,"Tier 2","Tier 3")) | T15: Wave 2 for Curity (Israeli network, InterCure / Bennu precedent) | U15: LinkedIn first | W15: Cascade map
A16: Orchard Global | B16: Cascade map - AUM < US$5b | C16: London / Singapore | D16: Structured credit, SRT, ABF | E16: n/a | F16: €20m+ | G16: Structured credit | H16: Global | I16: No | J16: Unknown | K16: 0 | L16: 0 | M16: 3 | N16: 1 | O16: 2 | P16: 1 | Q16: 2 | R16: =ROUND(SUMPRODUCT(K16:Q16,Scoring_Weights!$E$5:$K$5)/Scoring_Weights!$B$12*20,0) | S16: =IF(R16>=Scoring_Weights!$B$15,"Tier 1",IF(R16>=Scoring_Weights!$B$16,"Tier 2","Tier 3")) | T16: Not relevant | U16: n/a | W16: Cascade map
... A114: Blackstone (Credit & Insurance; ECRED) | B114: Cascade map - AUM > US$100b | C114: New York / London | D114: ECRED €2.6b NAV; infrastructure credit; 'Thermo Lysi structured product' idea in tracker via Argus | E114: n/a | F114: US$50m+ | G114: All | H114: Global | I114: Infrastructure | J114: Unknown | K114: 2 | L114: 0 | M114: 1 | N114: 1 | O114: 3 | P114: 2 | Q114: 1 | R114: =ROUND(SUMPRODUCT(K114:Q114,Scoring_Weights!$E$5:$K$5)/Scoring_Weights!$B$12*20,0) | S114: =IF(R114>=Scoring_Weights!$B$15,"Tier 1",IF(R114>=Scoring_Weights!$B$16,"Tier 2","Tier 3")) | T114: IVP-level; keep the Argus channel warm | U114: Warm via Argus | W114: Investor tracker; ecred.com

Sheet Investor_Universe
A1: Investor Universe
A2: Wider universe beyond the ABF map: direct lending, special situations, infrastructure and energy-transition credit, venture and growth debt, impact and DFI capital, cannabis-tolerant credit, placement agents and fund-finance providers. Scores are analyst judgement on the public evidence cited.
A4: Firm | B4: Category | C4: HQ / EU office | D4: Strategy / vehicle | E4: Fund size / AUM | F4: Ticket range | G4: Instruments | H4: Greece / Cyprus / S. Europe evidence | I4: Hard-asset / FOAK evidence | J4: Cannabis stance | K4: S1 IPL fit | L4: S2 CPEF fit | M4: S3 Ticket | N4: S4 Geography | O4: S5 Risk appetite | P4: S6 Warm path | Q4: S7 Speed | R4: Weighted score | S4: Tier | T4: Best use for Impactus | U4: Recommended channel | V4: Warm path via | W4: Source URL
A5: EIB - Cleantech Equity & Growth Capital Division (venture debt) | B5: DFI - venture debt | C5: Luxembourg | D5: EIB venture debt (quasi-equity for FOAK cleantech); Joltie €17.5m Greece precedent | E5: EIB Group Greece €3.5b (2025) | F5: €7.5m to €50m | G5: Venture debt: cash + PIK + warrants | H5: Record Greek lending; direct engagement with Impactus Feb-Sep 2026 | I5: Designed for FOAK; declined 30-04-2026 as 'mezzanine risk without equity reward'; re-engaged Sep 2026 via Sirec | J5: No formal exclusion; no precedent | K5: 5 | L5: 1 | M5: 5 | N5: 5 | O5: 4 | P5: 5 | Q5: 2 | R5: =ROUND(SUMPRODUCT(K5:Q5,Scoring_Weights!$E$5:$K$5)/Scoring_Weights!$B$12*20,0) | S5: =IF(R5>=Scoring_Weights!$B$15,"Tier 1",IF(R5>=Scoring_Weights!$B$16,"Tier 2","Tier 3")) | T5: Reopen VD at €20m to €35m with equity-like upside (higher warrant coverage) so the 'reward' objection is answered | U5: Warm - existing thread | V5: Sirec (Papageorgantas); direct to Casorati / Mitrakas | W5: Outlook threads Feb-Sep 2026; EIB press 2026-041
A6: Hellenic Innovation & Infrastructure Fund (HIIF) | B6: Greek impact / infra investor | C6: Athens | D6: Assessing €35m VD tranche at 10% blended; market-operator (state aid) test at IC | E6: n/a | F6: €10m to €50m | G6: Venture debt / hybrid | H6: Greek | I6: Live DD on Thermo Lysi since Jul 2026 | J6: n/a | K6: 5 | L6: 0 | M6: 5 | N6: 5 | O6: 4 | P6: 5 | Q6: 3 | R6: =ROUND(SUMPRODUCT(K6:Q6,Scoring_Weights!$E$5:$K$5)/Scoring_Weights!$B$12*20,0) | S6: =IF(R6>=Scoring_Weights!$B$15,"Tier 1",IF(R6>=Scoring_Weights!$B$16,"Tier 2","Tier 3")) | T6: Re-cut as staged commitment (development tranche now, construction tranche at FID); keep them ahead of the PMO reset | U6: Warm - existing thread | V6: Direct: Vlachos, Fragos, Giannakopoulos | W6: Outlook 'Impactus Group - HIIF' Jul-Aug 2026
A7: Credia Bank (Structured Finance) | B7: Greek bank - senior project debt | C7: Athens | D7: Senior facility term sheet c.€77.4m, 1.5x DSCR; LOI 6.5% / 4+10y / 1.3x avg DSCR | E7: n/a | F7: €20m to €100m | G7: Senior project finance, VAT facility | H7: Greek | I7: Term sheet on 20ktpa; 45ktpa update in credit process | J7: n/a | K7: 5 | L7: 0 | M7: 5 | N7: 5 | O7: 2 | P7: 5 | Q7: 2 | R7: =ROUND(SUMPRODUCT(K7:Q7,Scoring_Weights!$E$5:$K$5)/Scoring_Weights!$B$12*20,0) | S7: =IF(R7>=Scoring_Weights!$B$15,"Tier 1",IF(R7>=Scoring_Weights!$B$16,"Tier 2","Tier 3")) | T7: Deliver firm EPC price, TDD and CP list; run one competing bank (Piraeus or Eurobank PF) for tension | U7: Warm - existing thread | V7: Venero (Chatzilias); direct to Mitrou | W7: Credia LOI thread Jul-Aug 2026
A8: Sirec Energy | B8: Greek energy fund - co-investor | C8: Athens | D8: Executed TS Mar 2026 at c.€34m post-money Thermo Lysi; advising on EIB | E8: n/a | F8: €2m to €10m | G8: Equity | H8: Greek | I8: Co-investor in Thermo Lysi | J8: n/a | K8: 4 | L8: 0 | M8: 4 | N8: 5 | O8: 4 | P8: 5 | Q8: 4 | R8: =ROUND(SUMPRODUCT(K8:Q8,Scoring_Weights!$E$5:$K$5)/Scoring_Weights!$B$12*20,0) | S8: =IF(R8>=Scoring_Weights!$B$15,"Tier 1",IF(R8>=Scoring_Weights!$B$16,"Tier 2","Tier 3")) | T8: Reference co-investor; ask for Greek bank and EIB introductions and a follow-on | U8: Warm | V8: Direct: Papageorgantas, Alissandratos | W8: Outlook 17-09-2026
A9: Piraeus Bank (Structured / Green Finance) | B9: Greek bank - project finance | C9: Athens | D9: Largest Greek PF desk; EIB €950m on-lending line; RRF green loans | E9: Assets >€75b [K] | F9: €20m to €150m | G9: Senior project finance | H9: Greek | I9: Waste / energy SPVs [K] | J9: Unknown | K9: 4 | L9: 1 | M9: 5 | N9: 5 | O9: 2 | P9: 3 | Q9: 2 | R9: =ROUND(SUMPRODUCT(K9:Q9,Scoring_Weights!$E$5:$K$5)/Scoring_Weights!$B$12*20,0) | S9: =IF(R9>=Scoring_Weights!$B$15,"Tier 1",IF(R9>=Scoring_Weights!$B$16,"Tier 2","Tier 3")) | T9: Competing senior bid to Credia; also Ethniki Insurance (Piraeus-owned) as LP | U9: Warm intro via Axia / PwC Greece | V9: Axia (Achilleoudis); PwC Greece (Kantounis) | W9: EIB press 2026-041 [K]
A10: Eurobank (Project Finance) and Eurobank Cyprus | B10: Greek / Cypriot bank | C10: Athens / Nicosia | D10: Project finance Greece; Eurobank Cyprus depositary and first InvestEU guarantee in Cyprus (€62.5m) | E10: n/a | F10: €10m to €100m | G10: Senior PF; small capital-call line | H10: Greek and Cypriot | I10: PF desk for energy / waste [K] | J10: Unknown | K10: 4 | L10: 1 | M10: 5 | N10: 5 | O10: 2 | P10: 3 | Q10: 3 | R10: =ROUND(SUMPRODUCT(K10:Q10,Scoring_Weights!$E$5:$K$5)/Scoring_Weights!$B$12*20,0) | S10: =IF(R10>=Scoring_Weights!$B$15,"Tier 1",IF(R10>=Scoring_Weights!$B$16,"Tier 2","Tier 3")) | T10: Second competing senior bid; capital-call line for the PE Fund (ex-CPEF) | U10: Warm intro via Argus (depositary relationship) | V10: Argus Management | W10: EIF press 2025-343; research briefing
A11: Alpha Bank (Wholesale / Wealth Management Greece) | B11: Greek bank | C11: Athens | D11: Cooperation discussion Sep 2026; wealth-management distribution of Impactus products | E11: n/a | F11: €10m to €100m PF; private-placement distribution | G11: Senior PF; distribution | H11: Greek | I11: PF desk [K] | J11: Unknown | K11: 3 | L11: 2 | M11: 4 | N11: 5 | O11: 2 | P11: 4 | Q11: 3 | R11: =ROUND(SUMPRODUCT(K11:Q11,Scoring_Weights!$E$5:$K$5)/Scoring_Weights!$B$12*20,0) | S11: =IF(R11>=Scoring_Weights!$B$15,"Tier 1",IF(R11>=Scoring_Weights!$B$16,"Tier 2","Tier 3")) | T11: Distribution agreement for professional clients; PF desk as third senior bid | U11: Warm - existing thread | V11: Miltos Michailas (AM relationship) | W11: Outlook 09-09-2026
A12: National Bank of Greece (Project Finance) | B12: Greek bank | C12: Athens | D12: €250m EIB green line; €200m agri / bioeconomy line 2026 | E12: n/a | F12: €20m to €150m | G12: Senior PF | H12: Greek | I12: Green / bioeconomy lines [K] | J12: Unknown | K12: 3 | L12: 1 | M12: 4 | N12: 5 | O12: 2 | P12: 2 | Q12: 2 | R12: =ROUND(SUMPRODUCT(K12:Q12,Scoring_Weights!$E$5:$K$5)/Scoring_Weights!$B$12*20,0) | S12: =IF(R12>=Scoring_Weights!$B$15,"Tier 1",IF(R12>=Scoring_Weights!$B$16,"Tier 2","Tier 3")) | T12: Fourth senior option; bioeconomy line could suit Curity (agri) | U12: Cold / via PwC Greece | V12: PwC Greece | W12: EIB press 2026-041
A13: Hellenic Development Bank (HDB) / HDBI | B13: Greek national promotional bank | C13: Athens | D13: Green Co-Financing (40% interest-free); HDBI is LP in Elikonos 3 | E13: €2b RRF allocation | F13: €1m to €20m | G13: Co-financed loans; fund-of-funds | H13: Greek | I13: RES / energy efficiency focus; disbursement deadline 31-08-2026 | J13: Unknown | K13: 2 | L13: 1 | M13: 4 | N13: 5 | O13: 1 | P13: 2 | Q13: 2 | R13: =ROUND(SUMPRODUCT(K13:Q13,Scoring_Weights!$E$5:$K$5)/Scoring_Weights!$B$12*20,0) | S13: =IF(R13>=Scoring_Weights!$B$15,"Tier 1",IF(R13>=Scoring_Weights!$B$16,"Tier 2","Tier 3")) | T13: Check 2027 windows; HDBI as LP in a Greek-domiciled feeder | U13: Cold / via PwC Greece | V13: PwC Greece | W13: hdb.gr; research briefing
A14: Growthfund / HCAP | B14: Greek sovereign holding | C14: Athens | D14: c.€6b state assets; evolving into National Investment Fund for Growth; BlackRock FMA | E14: €6b | F14: €10m+ | G14: Equity / fund commitments | H14: Greek | I14: Strategic infrastructure | J14: Unlikely | K14: 2 | L14: 0 | M14: 3 | N14: 5 | O14: 2 | P14: 1 | Q14: 1 | R14: =ROUND(SUMPRODUCT(K14:Q14,Scoring_Weights!$E$5:$K$5)/Scoring_Weights!$B$12*20,0) | S14: =IF(R14>=Scoring_Weights!$B$15,"Tier 1",IF(R14>=Scoring_Weights!$B$16,"Tier 2","Tier 3")) | T14: IVP-level conversation only | U14: Cold | W14: growthfund.gr
A15: Elikonos Capital Partners | B15: Greek lower-mid credit / equity AIF | C15: Athens | D15: Elikonos 3 €175m first close (HDBI, EIF, EBRD) | E15: €175m | F15: €3m to €15m | G15: Hybrid, mezz, equity | H15: Greek | I15: SME growth; EIF-backed (state-aid sensitive) | J15: Excluded in practice (EIF LP) | K15: 2 | L15: 1 | M15: 5 | N15: 5 | O15: 2 | P15: 4 | Q15: 3 | R15: =ROUND(SUMPRODUCT(K15:Q15,Scoring_Weights!$E$5:$K$5)/Scoring_Weights!$B$12*20,0) | S15: =IF(R15>=Scoring_Weights!$B$15,"Tier 1",IF(R15>=Scoring_Weights!$B$16,"Tier 2","Tier 3")) | T15: Curity growth facility once EBITDA positive; 'Pantelis Solomis' in the tracker is the warm path | U15: Warm - in tracker | V15: AM (Pantelis Solomis) | W15: elikonos.com
A16: Halcyon Equity Partners | B16: Greek AIF | C16: Athens | D16: €208m AUM | E16: €208m | F16: €3m to €15m | G16: Equity / hybrid | H16: Greek | I16: SME | J16: Unknown | K16: 2 | L16: 1 | M16: 4 | N16: 5 | O16: 2 | P16: 1 | Q16: 3 | R16: =ROUND(SUMPRODUCT(K16:Q16,Scoring_Weights!$E$5:$K$5)/Scoring_Weights!$B$12*20,0) | S16: =IF(R16>=Scoring_Weights!$B$15,"Tier 1",IF(R16>=Scoring_Weights!$B$16,"Tier 2","Tier 3")) | T16: Curity / IPL co-investor | U16: Cold | W16: halcyonequitypartners.com
A17: Waterwheel Capital Management | B17: Greek credit specialist | C17: Athens / London | D17: Hellenic Credit I DAC; Hellenic Opportunities | E17: n/a | F17: €5m to €30m | G17: Special situations credit | H17: Greek | I17: Distressed / NPL heritage | J17: Unknown | K17: 3 | L17: 1 | M17: 4 | N17: 5 | O17: 3 | P17: 1 | Q17: 3 | R17: =ROUND(SUMPRODUCT(K17:Q17,Scoring_Weights!$E$5:$K$5)/Scoring_Weights!$B$12*20,0) | S17: =IF(R17>=Scoring_Weights!$B$15,"Tier 1",IF(R17>=Scoring_Weights!$B$16,"Tier 2","Tier 3")) | T17: Holdco / IPL hybrid; Greek credit expertise | U17: Cold | W17: aum13f.com
A18: Kartesia | B18: Lower-mid-market private credit | C18: Luxembourg / Brussels; Madrid | D18: Kartesia Credit Opportunities VI €1.3b (Jul 2025); c.€6b AUM; on the Cascade map (<US$5b ABF bucket) | E18: €1.3b (KCO VI) | F18: €10m to €60m | G18: Senior, unitranche, hybrid, PIK | H18: Southern Europe team (Iberia, Italy) [K] | I18: Sponsorless SMEs; some real-asset backed | J18: Unknown | K18: 3 | L18: 2 | M18: 4 | N18: 3 | O18: 3 | P18: 1 | Q18: 3 | R18: =ROUND(SUMPRODUCT(K18:Q18,Scoring_Weights!$E$5:$K$5)/Scoring_Weights!$B$12*20,0) | S18: =IF(R18>=Scoring_Weights!$B$15,"Tier 1",IF(R18>=Scoring_Weights!$B$16,"Tier 2","Tier 3")) | T18: Holdco / sponsor-level hybrid for IPL at FID; Curity growth line later | U18: Cold - LinkedIn first | W18: kartesia.com press 04-07-2025
A19: Capza (BNPP AM Alts) | B19: Mid-market private debt | C19: Paris / Madrid | D19: Capza PD 7 c.€1.4b first close; AUM >€9b; Transition strategy | E19: €1.4b | F19: €10m to €80m | G19: Unitranche, mezz | H19: Iberia / Italy | I19: Mid-market corporates | J19: Unknown | K19: 2 | L19: 2 | M19: 3 | N19: 2 | O19: 2 | P19: 1 | Q19: 3 | R19: =ROUND(SUMPRODUCT(K19:Q19,Scoring_Weights!$E$5:$K$5)/Scoring_Weights!$B$12*20,0) | S19: =IF(R19>=Scoring_Weights!$B$15,"Tier 1",IF(R19>=Scoring_Weights!$B$16,"Tier 2","Tier 3")) | T19: Wave 2 | U19: Cold | W19: alts.axa-im.com press
A20: Muzinich & Co (Pan-European Private Debt) | B20: Lower-mid-market private debt | C20: London / Milan / Madrid | D20: c.US$38b AUM; European private debt ELTIF; parallel lending with banks | E20: n/a | F20: €5m to €30m | G20: Senior / unitranche; parallel lending | H20: Italy, Spain, France; no Greek office | I20: Mid-market | J20: Unknown | K20: 2 | L20: 2 | M20: 5 | N20: 2 | O20: 2 | P20: 1 | Q20: 3 | R20: =ROUND(SUMPRODUCT(K20:Q20,Scoring_Weights!$E$5:$K$5)/Scoring_Weights!$B$12*20,0) | S20: =IF(R20>=Scoring_Weights!$B$15,"Tier 1",IF(R20>=Scoring_Weights!$B$16,"Tier 2","Tier 3")) | T20: Curity growth line; ELTIF distribution model to study | U20: Cold | W20: muzinich.com
A21: Beechbrook Capital | B21: Lower-mid-market SME credit | C21: London | D21: UK SME Credit IV £151m first close; €2m to €25m bites | E21: £250m target | F21: €2m to €25m | G21: Senior, unitranche, mezz | H21: UK / Ireland mainly | I21: SMEs with EBITDA ≤£15m | J21: Unknown | K21: 1 | L21: 2 | M21: 5 | N21: 1 | O21: 2 | P21: 1 | Q21: 4 | R21: =ROUND(SUMPRODUCT(K21:Q21,Scoring_Weights!$E$5:$K$5)/Scoring_Weights!$B$12*20,0) | S21: =IF(R21>=Scoring_Weights!$B$15,"Tier 1",IF(R21>=Scoring_Weights!$B$16,"Tier 2","Tier 3")) | T21: Reference for terms; unlikely to lend in Greece | U21: Cold | W21: ACI 07-11-2024
A22: Hayfin Capital Management (Special Opportunities) | B22: Special situations / direct lending | C22: London | D22: DLF V >€15b (Jul 2026); Special Opportunities strategy; on Cascade map (US$20-100b) | E22: >€15b | F22: €25m to €150m | G22: Senior, special sits, hybrid | H22: Pan-European incl. Southern Europe | I22: Special-opportunities book takes asset-backed / complex credits | J22: Unknown | K22: 3 | L22: 1 | M22: 2 | N22: 3 | O22: 4 | P22: 1 | Q22: 2 | R22: =ROUND(SUMPRODUCT(K22:Q22,Scoring_Weights!$E$5:$K$5)/Scoring_Weights!$B$12*20,0) | S22: =IF(R22>=Scoring_Weights!$B$15,"Tier 1",IF(R22>=Scoring_Weights!$B$16,"Tier 2","Tier 3")) | T22: IVP-level or a €35m+ hybrid at FID; ticket floor is the issue | U22: Cold | W22: hayfin.com 2026
A23: Tikehau Capital (Private Debt / Special Opportunities / Decarbonisation) | B23: Private debt, special sits, transition | C23: Paris / Madrid / Milan | D23: European DL VI €5.2b (Jul 2026); special sits €1b+ (H1 2026); on Cascade map | E23: €5.2b | F23: €20m to €100m | G23: Senior, special sits, decarbonisation equity | H23: Iberia, Italy; no Greek office | I23: Decarbonisation strategy invests in transition assets | J23: Unknown | K23: 3 | L23: 1 | M23: 3 | N23: 3 | O23: 3 | P23: 1 | Q23: 2 | R23: =ROUND(SUMPRODUCT(K23:Q23,Scoring_Weights!$E$5:$K$5)/Scoring_Weights!$B$12*20,0) | S23: =IF(R23>=Scoring_Weights!$B$15,"Tier 1",IF(R23>=Scoring_Weights!$B$16,"Tier 2","Tier 3")) | T23: Special Opportunities or Decarbonisation team for IVP / IPL | U23: Cold - LinkedIn first | W23: ACI 24-07-2026
A24: Pemberton Asset Management | B24: Mid-market private credit; NAV | C24: London | D24: MMD IV + Senior Loan €6.1b; NAV Core I US$1.7b; on Cascade map | E24: US$29b AUM | F24: €30m to €150m | G24: Senior, unitranche, NAV | H24: Pan-European | I24: Corporate | J24: Unknown | K24: 1 | L24: 1 | M24: 2 | N24: 2 | O24: 2 | P24: 1 | Q24: 2 | R24: =ROUND(SUMPRODUCT(K24:Q24,Scoring_Weights!$E$5:$K$5)/Scoring_Weights!$B$12*20,0) | S24: =IF(R24>=Scoring_Weights!$B$15,"Tier 1",IF(R24>=Scoring_Weights!$B$16,"Tier 2","Tier 3")) | T24: Tier 3 - keep informed | U24: Cold | W24: creditflux 14-05-2025
A25: Arcmont Asset Management (Impact Lending) | B25: Direct lending | C25: London | D25: DL V €15-17b target; Impact Lending strategy | E25: >€11b raised | F25: €30m to €200m | G25: Senior / unitranche | H25: Pan-European | I25: Impact Lending sleeve | J25: Unknown | K25: 1 | L25: 1 | M25: 2 | N25: 2 | O25: 2 | P25: 1 | Q25: 2 | R25: =ROUND(SUMPRODUCT(K25:Q25,Scoring_Weights!$E$5:$K$5)/Scoring_Weights!$B$12*20,0) | S25: =IF(R25>=Scoring_Weights!$B$15,"Tier 1",IF(R25>=Scoring_Weights!$B$16,"Tier 2","Tier 3")) | T25: Tier 3 | U25: Cold | W25: PitchBook 2026
A26: Blantyre Capital | B26: Special situations | C26: London | D26: Special Situations Fund II | E26: n/a | F26: €10m to €75m | G26: Bespoke capital solutions, PIK | H26: Pan-European incl. Southern Europe [K] | I26: Complex / stressed credits | J26: Unknown | K26: 3 | L26: 1 | M26: 4 | N26: 3 | O26: 5 | P26: 1 | Q26: 3 | R26: =ROUND(SUMPRODUCT(K26:Q26,Scoring_Weights!$E$5:$K$5)/Scoring_Weights!$B$12*20,0) | S26: =IF(R26>=Scoring_Weights!$B$15,"Tier 1",IF(R26>=Scoring_Weights!$B$16,"Tier 2","Tier 3")) | T26: €35m hybrid at 14% to 18% all-in | U26: Cold - LinkedIn first | W26: PitchBook fund profile
A27: Cheyne Capital (Strategic Value Credit) | B27: Special situations / real assets | C27: London | D27: Strategic Value Credit; real-estate credit; on Cascade map | E27: n/a | F27: €20m to €150m | G27: Opportunistic credit, real-asset lending | H27: Pan-European | I27: Real assets | J27: Unknown | K27: 3 | L27: 1 | M27: 3 | N27: 2 | O27: 4 | P27: 1 | Q27: 2 | R27: =ROUND(SUMPRODUCT(K27:Q27,Scoring_Weights!$E$5:$K$5)/Scoring_Weights!$B$12*20,0) | S27: =IF(R27>=Scoring_Weights!$B$15,"Tier 1",IF(R27>=Scoring_Weights!$B$16,"Tier 2","Tier 3")) | T27: Wave 2 | U27: Cold | W27: cheynecapital.com
... A45: Tiger Infrastructure Partners | B45: Growth infrastructure equity | C45: New York / London | D45: Bolder Industries (Antwerp pyrolysis) growth investment Feb 2025; US$25m to US$100m tickets | E45: n/a | F45: US$25m to US$100m | G45: Growth equity | H45: Europe (Antwerp) | I45: Direct pyrolysis precedent | J45: n/a | K45: 4 | L45: 0 | M45: 3 | N45: 2 | O45: 5 | P45: 1 | Q45: 3 | R45: =ROUND(SUMPRODUCT(K45:Q45,Scoring_Weights!$E$5:$K$5)/Scoring_Weights!$B$12*20,0) | S45: =IF(R45>=Scoring_Weights!$B$15,"Tier 1",IF(R45>=Scoring_Weights!$B$16,"Tier 2","Tier 3")) | T45: Wave 1: IVP anchor conversation; they have underwritten Pyrum-comparable risk | U45: Cold - LinkedIn first | W45: PR Newswire Feb 2025
A46: Antin Infrastructure Partners | B46: Infrastructure equity | C46: Paris | D46: Infiniteria (Enviro / Michelin) tyre-pyrolysis JV - now in dispute with Enviro | E46: n/a | F46: €100m+ | G46: Equity | H46: Europe | I46: Direct pyrolysis precedent (troubled) | J46: n/a | K46: 3 | L46: 0 | M46: 1 | N46: 2 | O46: 4 | P46: 3 | Q46: 1 | R46: =ROUND(SUMPRODUCT(K46:Q46,Scoring_Weights!$E$5:$K$5)/Scoring_Weights!$B$12*20,0) | S46: =IF(R46>=Scoring_Weights!$B$15,"Tier 1",IF(R46>=Scoring_Weights!$B$16,"Tier 2","Tier 3")) | T46: Later-stage buyer; 'Secure EoI' already in tracker | U46: Warm - in tracker (Argus) | V46: Argus | W46: antin-ip.com; Enviro releases 2026
A47: Novo Holdings / A.P. Moller Holding | B47: Strategic / evergreen investors | C47: Copenhagen | D47: €75m equity into Circtec (Delfzijl tyre pyrolysis) | E47: n/a | F47: €25m+ | G47: Equity | H47: Europe | I47: Direct pyrolysis precedent | J47: n/a | K47: 3 | L47: 0 | M47: 2 | N47: 1 | O47: 4 | P47: 1 | Q47: 1 | R47: =ROUND(SUMPRODUCT(K47:Q47,Scoring_Weights!$E$5:$K$5)/Scoring_Weights!$B$12*20,0) | S47: =IF(R47>=Scoring_Weights!$B$15,"Tier 1",IF(R47>=Scoring_Weights!$B$16,"Tier 2","Tier 3")) | T47: IVP-level; Circtec is a competitor reference | U47: Cold | W47: apmoller.com May 2024
A48: Invest-NL | B48: Dutch promotional investor | C48: Amsterdam | D48: Xycle, Pryme (chemical recycling) | E48: n/a | F48: €5m to €30m | G48: Equity / debt | H48: Netherlands only | I48: Chemical recycling precedent | J48: n/a | K48: 1 | L48: 0 | M48: 3 | N48: 0 | O48: 4 | P48: 1 | Q48: 2 | R48: =ROUND(SUMPRODUCT(K48:Q48,Scoring_Weights!$E$5:$K$5)/Scoring_Weights!$B$12*20,0) | S48: =IF(R48>=Scoring_Weights!$B$15,"Tier 1",IF(R48>=Scoring_Weights!$B$16,"Tier 2","Tier 3")) | T48: Not eligible (NL mandate); reference only | U48: n/a | W48: invest-nl.nl
A49: Infinity Recycling (Circular Plastics Fund) | B49: Circular-economy VC / growth | C49: Rotterdam | D49: CPF €175m (EIF €50m); Alterra, Itero, Pryme | E49: €175m | F49: €5m to €15m | G49: Equity | H49: Europe | I49: Plastics chemical recycling | J49: n/a | K49: 2 | L49: 0 | M49: 4 | N49: 1 | O49: 4 | P49: 1 | Q49: 3 | R49: =ROUND(SUMPRODUCT(K49:Q49,Scoring_Weights!$E$5:$K$5)/Scoring_Weights!$B$12*20,0) | S49: =IF(R49>=Scoring_Weights!$B$15,"Tier 1",IF(R49>=Scoring_Weights!$B$16,"Tier 2","Tier 3")) | T49: Co-investor in IVP; plastics not tyres | U49: Cold | W49: Packaging Europe
A50: Emerald Technology Ventures | B50: Industrial innovation VC | C50: Zurich | D50: Emerald Industrial Innovation Fund; corporate LPs (BASF etc.) | E50: n/a | F50: €3m to €15m | G50: Equity | H50: Europe | I50: Industrial cleantech | J50: n/a | K50: 2 | L50: 0 | M50: 3 | N50: 1 | O50: 4 | P50: 1 | Q50: 3 | R50: =ROUND(SUMPRODUCT(K50:Q50,Scoring_Weights!$E$5:$K$5)/Scoring_Weights!$B$12*20,0) | S50: =IF(R50>=Scoring_Weights!$B$15,"Tier 1",IF(R50>=Scoring_Weights!$B$16,"Tier 2","Tier 3")) | T50: Co-investor at sponsor level | U50: Cold | W50: emerald.vc [K]
A51: Kreos Capital (BlackRock) | B51: Venture / growth debt | C51: London | D51: >US$7b committed, 830+ deals; Aris Constantinides (General Partner) is Greek | E51: n/a | F51: €5m to €50m | G51: Growth debt with warrants | H51: Pan-European | I51: VC-backed revenue companies | J51: No exclusion located | K51: 2 | L51: 3 | M51: 5 | N51: 2 | O51: 3 | P51: 2 | Q51: 4 | R51: =ROUND(SUMPRODUCT(K51:Q51,Scoring_Weights!$E$5:$K$5)/Scoring_Weights!$B$12*20,0) | S51: =IF(R51>=Scoring_Weights!$B$15,"Tier 1",IF(R51>=Scoring_Weights!$B$16,"Tier 2","Tier 3")) | T51: Curity growth line at 12 months of audited sales; Greek partner as door-opener | U51: LinkedIn first (Constantinides) | V51: Greek diaspora angle | W51: tulacap.com; research briefing
A52: Claret Capital Partners | B52: Growth debt | C52: Dublin / London | D52: Fund IV €575m | E52: €575m | F52: €3m to €30m | G52: Growth debt | H52: Pan-European | I52: VC-backed | J52: No exclusion located | K52: 1 | L52: 3 | M52: 5 | N52: 2 | O52: 3 | P52: 1 | Q52: 4 | R52: =ROUND(SUMPRODUCT(K52:Q52,Scoring_Weights!$E$5:$K$5)/Scoring_Weights!$B$12*20,0) | S52: =IF(R52>=Scoring_Weights!$B$15,"Tier 1",IF(R52>=Scoring_Weights!$B$16,"Tier 2","Tier 3")) | T52: Curity growth line 2027 | U52: Cold | W52: TNW
A53: Atempo Growth | B53: Growth debt | C53: London / Madrid | D53: Fund II >€455m; c.€850m AUM; Santander backing | E53: €455m | F53: €3m to €25m | G53: Growth debt | H53: Southern Europe presence (Madrid) | I53: VC-backed | J53: No exclusion located | K53: 1 | L53: 3 | M53: 5 | N53: 3 | O53: 3 | P53: 1 | Q53: 4 | R53: =ROUND(SUMPRODUCT(K53:Q53,Scoring_Weights!$E$5:$K$5)/Scoring_Weights!$B$12*20,0) | S53: =IF(R53>=Scoring_Weights!$B$15,"Tier 1",IF(R53>=Scoring_Weights!$B$16,"Tier 2","Tier 3")) | T53: Curity growth line 2027 | U53: Cold | W53: capitalranking.com
A54: Chicago Atlantic (REFI / BDC) | B54: Specialist cannabis credit | C54: Chicago | D54: REFI US$453m, 26 borrowers, 15.8% YTM (30-06-2026); co-founder John Mazarakis is Greek-American | E54: US$453m | F54: US$5m to US$50m | G54: Senior secured cannabis loans | H54: US only to date | I54: n/a | J54: Core mandate | K54: 0 | L54: 4 | M54: 5 | N54: 1 | O54: 4 | P54: 1 | Q54: 3 | R54: =ROUND(SUMPRODUCT(K54:Q54,Scoring_Weights!$E$5:$K$5)/Scoring_Weights!$B$12*20,0) | S54: =IF(R54>=Scoring_Weights!$B$15,"Tier 1",IF(R54>=Scoring_Weights!$B$16,"Tier 2","Tier 3")) | T54: Wave 1 for CPEF: test European appetite; €3m to €10m at 13% to 16% | U54: LinkedIn first (Mazarakis) | V54: Greek diaspora angle | W54: REFI 10-Q via research briefing
A55: Advanced Flower Capital (AFC Gamma) | B55: Specialist cannabis credit | C55: West Palm Beach | D55: US$290m, 17 loans, 13.2% yield, 35.7% non-accrual | E55: US$290m | F55: US$5m to US$40m | G55: Senior secured | H55: US only | I55: n/a | J55: Core mandate | K55: 0 | L55: 3 | M55: 5 | N55: 0 | O55: 3 | P55: 1 | Q55: 2 | R55: =ROUND(SUMPRODUCT(K55:Q55,Scoring_Weights!$E$5:$K$5)/Scoring_Weights!$B$12*20,0) | S55: =IF(R55>=Scoring_Weights!$B$15,"Tier 1",IF(R55>=Scoring_Weights!$B$16,"Tier 2","Tier 3")) | T55: Wave 2; distressed book limits appetite | U55: Cold | W55: AFCG 10-Q via research briefing
A56: Artemis Growth Partners | B56: Cannabis growth equity / hybrid | C56: London / New York | D56: Fund VII US$200m target, c.75% Europe; c.US$400m AUM; Bloomwell investor | E56: US$200m | F56: US$5m to US$25m | G56: Equity / hybrid | H56: Europe focus | I56: n/a | J56: Core mandate | K56: 0 | L56: 5 | M56: 5 | N56: 2 | O56: 4 | P56: 1 | Q56: 3 | R56: =ROUND(SUMPRODUCT(K56:Q56,Scoring_Weights!$E$5:$K$5)/Scoring_Weights!$B$12*20,0) | S56: =IF(R56>=Scoring_Weights!$B$15,"Tier 1",IF(R56>=Scoring_Weights!$B$16,"Tier 2","Tier 3")) | T56: Wave 1 for CPEF: only fund with stated European allocation | U56: LinkedIn first | W56: research briefing (cannabis)
A57: Casa Verde Capital | B57: Cannabis VC | C57: Los Angeles | D57: Cansativa Series B lead (€13m, 2022); Sanity Group investor | E57: n/a | F57: US$2m to US$15m | G57: Equity | H57: Europe via portfolio | I57: n/a | J57: Core mandate | K57: 0 | L57: 3 | M57: 5 | N57: 1 | O57: 4 | P57: 1 | Q57: 3 | R57: =ROUND(SUMPRODUCT(K57:Q57,Scoring_Weights!$E$5:$K$5)/Scoring_Weights!$B$12*20,0) | S57: =IF(R57>=Scoring_Weights!$B$15,"Tier 1",IF(R57>=Scoring_Weights!$B$16,"Tier 2","Tier 3")) | T57: Wave 2 co-investor | U57: Cold | W57: research briefing (cannabis)
A58: Curaleaf International | B58: Strategic acquirer (cannabis) | C58: London | D58: US$500m senior secured notes 11.5% (Feb 2026) fund European M&A; bought Four 20 Pharma 100%; Clever Leaves Portugal assets; bid for Aurora | E58: n/a | F58: €2m to €50m | G58: Acquisition / offtake | H58: Germany, Portugal, UK | I58: n/a | J58: Core | K58: 0 | L58: 4 | M58: 5 | N58: 2 | O58: 5 | P58: 1 | Q58: 3 | R58: =ROUND(SUMPRODUCT(K58:Q58,Scoring_Weights!$E$5:$K$5)/Scoring_Weights!$B$12*20,0) | S58: =IF(R58>=Scoring_Weights!$B$15,"Tier 1",IF(R58>=Scoring_Weights!$B$16,"Tier 2","Tier 3")) | T58: Strategic buyer / offtaker for Curity; price discovery for the equity fallback | U58: LinkedIn / corporate development | W58: research briefing (cannabis)
...

Sheet Contacts
A1: Named contacts - decision-makers, with the channel most likely to get a reply
A2: Channel rule: warm intro > published email + LinkedIn note same day > LinkedIn InMail with a one-line hook > conference. Emails marked 'pattern - unverified' must be verified (bounce test / mutual contact) before sending. No data was purchased.
A4: Firm | B4: Person | C4: Title | D4: Category | E4: Target sub-fund | F4: LinkedIn URL | G4: Email | H4: Email status | I4: Warm path via | J4: Recommended channel | K4: Hook / message angle (one line) | L4: Confidence | M4: Evidence URL | N4: Owner | O4: Status
A5: EIB - Cleantech Equity & Growth Capital | B5: Alberto Casorati | C5: Cleantech Equity & Growth Capital Division | D5: DFI venture debt | E5: IPL | F5: https://www.linkedin.com/search/results/people/?keywords=Alberto%20Casorati%20European%20Investment%20Bank | G5: a.casorati@eib.org | H5: published | I5: Sirec (Papageorgantas) / direct thread | J5: =IF(I5<>"","Warm intro via "&I5,IF(H5="published","Email + LinkedIn note same day",IF(AND(H5="pattern - unverified",F5<>"not found"),"LinkedIn first; verify email then follow up",IF(F5<>"not found","LinkedIn InMail / connection note","Firm switchboard or conference")))) | K5: Answer the April objection head-on: offer equity-like reward (warrant coverage 15% to 20% or a conversion right) so VD is not 'mezzanine risk without reward' | L5: High | M5: Outlook thread Feb-Apr 2026 | N5: KM | O5: Not started
A6: EIB - Cleantech Equity & Growth Capital | B6: Stephan Mitrakas | C6: Investment Officer (VD team) | D6: DFI venture debt | E6: IPL | F6: https://www.linkedin.com/search/results/people/?keywords=Stephan%20Mitrakas%20European%20Investment%20Bank | G6: s.mitrakas@eib.org | H6: published | I6: Direct thread | J6: =IF(I6<>"","Warm intro via "&I6,IF(H6="published","Email + LinkedIn note same day",IF(AND(H6="pattern - unverified",F6<>"not found"),"LinkedIn first; verify email then follow up",IF(F6<>"not found","LinkedIn InMail / connection note","Firm switchboard or conference")))) | K6: Deliver the three items from the 14-09-2026 committee: Credia CP explainer, Continental supplier-approval letter, Sokolov comparison | L6: High | M6: Outlook 'EIB responses - follow up' 15-09-2026 | N6: KM | O6: Not started
A7: EIB | B7: Francois Gaudet | C7: EIB (cc on VD thread) | D7: DFI venture debt | E7: IPL | F7: https://www.linkedin.com/search/results/people/?keywords=Francois%20Gaudet%20European%20Investment%20Bank | G7: f.gaudet@eib.org | H7: published | I7: Direct thread | J7: =IF(I7<>"","Warm intro via "&I7,IF(H7="published","Email + LinkedIn note same day",IF(AND(H7="pattern - unverified",F7<>"not found"),"LinkedIn first; verify email then follow up",IF(F7<>"not found","LinkedIn InMail / connection note","Firm switchboard or conference")))) | K7: Senior sponsor inside EIB; copy on the reopened file | L7: Medium | M7: Outlook 30-04-2026 cc list | N7: KM | O7: Not started
A8: Hellenic Innovation & Infrastructure Fund (HIIF) | B8: Alexandros Vlachos | C8: Vice President, Investments | D8: Greek impact / infra investor | E8: IPL | F8: https://www.linkedin.com/search/results/people/?keywords=Alexandros%20Vlachos%20HIIF | G8: avlachos@hiif.gr | H8: published | I8: Direct thread | J8: =IF(I8<>"","Warm intro via "&I8,IF(H8="published","Email + LinkedIn note same day",IF(AND(H8="pattern - unverified",F8<>"not found"),"LinkedIn first; verify email then follow up",IF(F8<>"not found","LinkedIn InMail / connection note","Firm switchboard or conference")))) | K8: Staged commitment proposal; market-operator test framing (pari passu with Sirec equity) | L8: High | M8: Outlook 04-08-2026 | N8: KM | O8: Not started
A9: HIIF | B9: Stelios Fragos | C9: HIIF investment team | D9: Greek impact / infra investor | E9: IPL | F9: https://www.linkedin.com/search/results/people/?keywords=Stelios%20Fragos%20HIIF | G9: sfragos@hiif.gr | H9: published | I9: Direct thread | J9: =IF(I9<>"","Warm intro via "&I9,IF(H9="published","Email + LinkedIn note same day",IF(AND(H9="pattern - unverified",F9<>"not found"),"LinkedIn first; verify email then follow up",IF(F9<>"not found","LinkedIn InMail / connection note","Firm switchboard or conference")))) | K9: Same | L9: High | M9: Outlook 04-08-2026 | N9: KM | O9: Not started
A10: HIIF | B10: Andreas Giannakopoulos | C10: HIIF investment team | D10: Greek impact / infra investor | E10: IPL | F10: https://www.linkedin.com/search/results/people/?keywords=Andreas%20Giannakopoulos%20HIIF | G10: agiannakopoulos@hiif.gr | H10: published | I10: Direct thread | J10: =IF(I10<>"","Warm intro via "&I10,IF(H10="published","Email + LinkedIn note same day",IF(AND(H10="pattern - unverified",F10<>"not found"),"LinkedIn first; verify email then follow up",IF(F10<>"not found","LinkedIn InMail / connection note","Firm switchboard or conference")))) | K10: Same | L10: High | M10: Outlook 04-08-2026 | N10: KM | O10: Not started
A11: Credia Bank - Structured Finance | B11: Evangelos Mitrou | C11: Senior Relationship Manager, Structured Finance | D11: Greek bank - senior | E11: IPL | F11: https://www.linkedin.com/search/results/people/?keywords=Evangelos%20Mitrou%20Credia%20Bank | G11: mitrou.evangelos@crediabank.com | H11: published | I11: Venero (Chatzilias) | J11: =IF(I11<>"","Warm intro via "&I11,IF(H11="published","Email + LinkedIn note same day",IF(AND(H11="pattern - unverified",F11<>"not found"),"LinkedIn first; verify email then follow up",IF(F11<>"not found","LinkedIn InMail / connection note","Firm switchboard or conference")))) | K11: Firm EPC price 31-10; ask for the credit-committee calendar and the CP list in writing | L11: High | M11: Credia LOI thread Aug 2026 | N11: KM / Venero | O11: Not started
A12: Credia Bank - Structured Finance | B12: Christos Masouras | C12: Structured Finance | D12: Greek bank - senior | E12: IPL | F12: https://www.linkedin.com/search/results/people/?keywords=Christos%20Masouras%20Credia%20Bank | G12: masouras.christos@crediabank.com | H12: published | I12: Venero | J12: =IF(I12<>"","Warm intro via "&I12,IF(H12="published","Email + LinkedIn note same day",IF(AND(H12="pattern - unverified",F12<>"not found"),"LinkedIn first; verify email then follow up",IF(F12<>"not found","LinkedIn InMail / connection note","Firm switchboard or conference")))) | K12: Same | L12: High | M12: Credia LOI thread | N12: Venero | O12: Not started
