Workbook

Sheet Summary
B2: instrAction - two cases, every line, one workbook
B3: Expanded version of the two-case model of 04-08-2026. Case 1 = the sponsors' business plan of 17-07-2026 with EVERY line of their model on one page, to the 2029 returns. Case 2 = the company as we understand it after diligence and the management discussion of 04-08-2026, same depth. EUR m throughout.
B5: HOW TO READ THIS FILE
B6: BLUE figures are plugged from the sponsors' plan unchanged. RED figures are our additions - each carries its rationale alongside. Black figures are calculations.
B7: Each case sheet reads top to bottom as one argument: model controls > product economics > every revenue line > P&L > cash flow > balance sheet > the 2029 exit waterfall and the return on the EUR 2m.
B9: HEADLINE COMPARISON
C10: Case 1 - as given | D10: Case 2 - as understood | E10: Difference | J10: Notes
B11: Revenue 2026 H2 | C11: ='Case 1 - As Given'!C65 -> 0.21 | D11: ='Case 2 - As Understood'!C30 -> 0.3 | E11: =D11-C11 -> 0.09 | J11: Their four layers vs our three tracks.
B12: Revenue 2027 | C12: ='Case 1 - As Given'!D65 -> 2.17 | D12: ='Case 2 - As Understood'!D30 -> 0.9 | E12: =D12-C12 -> -1.27
B13: Revenue 2028 | C13: ='Case 1 - As Given'!E65 -> 6.86 | D13: ='Case 2 - As Understood'!E30 -> 3 | E13: =D13-C13 -> -3.86
B14: Revenue 2029 | C14: ='Case 1 - As Given'!F65 -> 8.02 | D14: ='Case 2 - As Understood'!F30 -> 6 | E14: =D14-C14 -> -2.02
B15: EBITDA 2028 | C15: ='Case 1 - As Given'!E71 -> 1.513 | D15: ='Case 2 - As Understood'!E54 -> -1.95 | E15: =D15-C15 -> -3.463 | J15: Their profitability year vs our still-negative year - findings 1 and 2 in money.
B16: EBITDA 2029 | C16: ='Case 1 - As Given'!F71 -> 1.643 | D16: ='Case 2 - As Understood'!F54 -> -0.246 | E16: =D16-C16 -> -1.889
B17: Lowest year-end cash | C17: =MIN('Case 1 - As Given'!C83:F83) -> 1.16 | D17: =MIN('Case 2 - As Understood'!C65:F65) -> 0.4695 | E17: =D17-C17 -> -0.6905 | J17: Case 2 stays positive only because of the assumed 2027 top-up.
B18: External equity required 2026-29 | C18: =4 -> 4 | D18: =9 -> 9 | E18: =D18-C18 -> 5 | J18: Their single EUR 4m close vs EUR 4m + the EUR 5m top-up their plan does not mention.
B19: Certification budget carried | C19: =0 -> 0 | D19: =2.2 -> 2.2 | E19: =D19-C19 -> 2.2 | J19: Finding 1 - zero in their use of funds; itemised on Case 2, section D.
B20: Exit equity value 2029 (base, 5.0x revenue) | C20: ='Case 1 - As Given'!C97 -> 43.84 | D20: ='Case 2 - As Understood'!C80 -> 30.4695 | E20: =D20-C20 -> -13.3705
B21: EUR 2m fully diluted share at exit | C21: ='Case 1 - As Given'!C108 -> 0.094733333 | D21: ='Case 2 - As Understood'!C92 -> 0.0758 | E21: =D21-C21 -> -0.018933333 | J21: Dilution x0.8 from the top-up round.
B22: EUR 2m participation - proceeds | C22: ='Case 1 - As Given'!C107 -> 4.1531093 | D22: ='Case 2 - As Understood'!C91 -> 2.3095881 | E22: =D22-C22 -> -1.8435212
B23: EUR 2m participation - multiple | C23: ='Case 1 - As Given'!D107 -> 2.0765547 | D23: ='Case 2 - As Understood'!D91 -> 1.1547941 | E23: =D23-C23 -> -0.92176062
B24: EUR 2m participation - IRR (3 yrs) | C24: ='Case 1 - As Given'!E107 -> 0.27579567 | D24: ='Case 2 - As Understood'!E91 -> 0.049143383
B26: SENSITIVITY - EUR 2m MULTIPLE OF MONEY BY EXIT EQUITY VALUE
B27: Exit equity value (EUR m) | C27: Case 1 - as given | D27: Case 2 - as understood | J27: Notes
B28: 35 | C28: =MAX(2,0.0947*B28)/2 -> 1.65725 | D28: =MAX(2,0.0758*B28)/2 -> 1.3265 | J28: The 1x preference floors the downside below c.EUR 22m exits.
B29: 55 | C29: =MAX(2,0.0947*B29)/2 -> 2.60425 | D29: =MAX(2,0.0758*B29)/2 -> 2.0845 | J29: The base the 1-pagers argue for - clears hurdles in both cases.
B30: 90 | C30: =MAX(2,0.0947*B30)/2 -> 4.2615 | D30: =MAX(2,0.0758*B30)/2 -> 3.411 | J30: A strategic contest (Xylem / Veolia class) over a certified, contracted asset.
B32: OUR FINDINGS IN FIVE LINES (detail: Case 2, section A)
B33: 1. No certification budget in the use of funds - yet the utility track and the exit multiple depend on starting it now (EUR 2.2m, itemised).
B34: 2. Frameworks are 12-month tests - volume and price only from c.Oct-27, which breaks 'profitable in 18-24 months' and forces a EUR 5m top-up in 2027.
B35: 3. AFFF is project revenue in a closing window (2030) - the recurring story behind the EUR 15m pre-money is the certification-gated utility track.
B36: 4. Destruction-only disposal for POP-loaded resin - contract it before volumes start; no regeneration revenue on Track 1.
B37: 5. The historic preference stack (c.EUR 12m of down rounds) is preserved in the term sheet - worth c.EUR 1m to us at mid exits; settle it in the documents.
B39: THE DIFFERENCE BETWEEN THE TWO CASES, IN ONE SENTENCE
B40: One year of commercial timing, EUR 2.2m of certification money the plan does not carry, a EUR 5m top-up round the plan does not mention - and the dilution that comes with it.
B42: Working model for discussion - not investment advice. Sources: business plan model and term sheet 17-07-2026 (all Case-1 lines transcribed from the model's Revenue Inputs and dashboard); management call 04-08-2026; Programme workbook and funding assessment 31-07-2026; Pyrum public record 2018-2026.

Sheet Case 1 - As Given
B2: Case 1 - the business plan as given (17-07-2026) - expanded to every line of their model
B3: One page: their model controls, product economics, all revenue lines, P&L, cash flow, balance sheet - leading to the 2029 exit waterfall and returns. BLUE = their figures unchanged. EUR m unless marked EUR k.
B5: STAGES ON THE PLAN'S TIMELINE
C6: 2026 H2 | D6: 2027 | E6: 2028 | F6: 2029 | G6: 2030 memo | H6: 2031 memo
C7: Second close + ramp-up | D7: Scale-up year | E7: EBITDA turns positive | F7: Exit window (projected) | G7: (beyond their exit story) | H7: (beyond their exit story)
B9: A. THEIR MODEL CONTROLS AND SCENARIO SETTINGS (sheet 'Instructions & Scenario')
B10: Active scenario | C10: Base | J10: Their model also carries Downside (pipeline x70%, top-down x60%, COGS x110%) and Upside (x130% / x150% / x95%) multiplier sets; everything below is the Base case they present.
B11: Probability weighting of named pipeline | C11: Yes | J11: Named-pipeline rows enter revenue at their sales-stage probability; existing and contracted rows enter at 100%.
B12: Starting cash (01-Jul-26) | C12: 0.35 | J12: EUR 0.35m opening cash - MIG's first EUR 1m of 2026 already inside.
B13: Planning grid | C13: monthly | J13: 30 monthly periods Jul-26 to Dec-28, then semi-annual to 2031. Annualised on this page.
B14: Default annual price increase / COGS improvement | C14: 0.02 | D14: 0.03 | J14: Applied to unit-priced products; top-down segment targets are entered as direct EUR revenue.
B16: B. PRODUCT ECONOMICS - THEIR FULL PRICE AND COGS TABLE
B17: Product (ID - group) | C17: Unit | D17: Std price EUR | E17: COGS EUR | F17: COGS % | G17: Gross margin | H17: Type | J17: Notes
B18: PFAS-BULK - PFAS resin bulk | C18: Liter | D18: 45 | E18: 12 | F18: 0.27 | G18: 0.733 | H18: Recurring | J18: Carries the two System-Integrator / Water-Utility segments - the volume story.
B19: PFAS-FILTER - filter / cartridge | C19: Unit | D19: 2500 | E19: 900 | F19: 0.36 | G19: 0.64 | H19: Recurring | J19: Carries the NA AFFF segment, the OEM segment and two named rows.
B20: PILOT - pilot equipment / MTU | C20: Project | D20: 35000 | E20: 18000 | F20: 0.51 | G20: 0.49 | H20: One-off | J20: Carries the EU AFFF (MTU) segment and three named rows; thinnest margin in the book.
B21: MTU - MTU operational | C21: Unit | D21: 35000 | E21: 18000 | F21: 0.51 | G21: 0.49 | H21: One-off | J21: Defined but unused by any revenue line in the Base case.
B22: HMR - heavy metal resin | C22: Liter | D22: 35 | E22: 10 | F22: 0.29 | G22: 0.714 | H22: Recurring | J22: Defined but unused - no revenue line attached.
B23: POU-MEDIA - point-of-use / OEM media | C23: Unit | D23: 12 | E23: 4 | F23: 0.33 | G23: 0.667 | H23: Recurring | J23: Carries the EU PoU/PoE segment.
B24: ANALYTICS - analytics / services | C24: Project | D24: 10000 | F24: 0.3 | G24: 0.7 | H24: One-off | J24: Defined but unused.
B25: ADVISORY - consulting services | C25: Project | D25: 10000 | F25: 0.3 | G25: 0.7 | H25: One-off | J25: Defined but unused.
B26: LICENSE - license / milestone | C26: Contract | F26: 0.05 | G26: 0.95 | H26: One-off | J26: Defined but unused - no licensing revenue anywhere in the plan.
B27: REGEN - regeneration / exchange service | C27: Service | D27: 15000 | F27: 0.35 | G27: 0.65 | H27: Recurring | J27: Defined but unused in the Base case - and the POP destruction constraint challenges it (see Case 2, finding 4).
B28: Six of ten products carry no revenue in the Base case - the plan runs on four: PILOT, PFAS-FILTER, PFAS-BULK, POU-MEDIA.
B30: C. THEIR SALES-STAGE PROBABILITY LADDER
B31: Sales stage | C31: Probability | J31: Definition (theirs, verbatim)
B32: Contracted / PO | C32: 1 | J32: Signed contract or purchase order received
B33: Awarded | C33: 0.9 | J33: Customer has made a clear decision in principle
B34: Contract Negotiation | C34: 0.75 | J34: Contract terms are being negotiated
B35: Commercial Proposal | C35: 0.5 | J35: Formal commercial proposal submitted
B36: Qualified Pilot | C36: 0.3 | J36: Specific pilot with a defined decision path
B37: Early Discussion | C37: 0.1 | J37: Initial customer discussion
B38: Unidentified | C38: n/a | J38: No named customer yet - enters revenue at 100% of the segment target, unweighted
B39: The asymmetry to note: a named customer at first discussion counts at 10% - a target segment with NO customer at all counts at 100%.
B41: D. THE REVENUE BUILD-UP - EVERY LINE IN THEIR MODEL (EUR k, as they enter the P&L)
B42: EUR k | C42: 2026 H2 | D42: 2027 | E42: 2028 | F42: 2029 | G42: 2030 memo | H42: 2031 memo | J42: Notes
B43: Named customers - bottom-up (probability-weighted values, i.e. what their model books):
B44: REV-001 Existing - pilot equipment (Awarded, 90%) | C44: 35 | D44: 0 | E44: 0 | F44: 0 | G44: 0 | H44: 0 | J44: 'Accumulated existing pipeline', PILOT product. EUR 8k Jul-26 + 5k Aug + 22k Sep - all of it in three months of 2026.
B45: REV-002 Existing - filters (Awarded, 90%) | C45: 6 | D45: 0 | E45: 0 | F45: 0 | G45: 0 | H45: 0 | J45: PFAS-FILTER. EUR 2k each Jul / Sep / Oct-26.
B46: REV-003 Contracted - pilots (Contract Negotiation, 75%) | C46: 46 | D46: 37 | E46: 0 | F46: 0 | G46: 0 | H46: 0 | J46: PILOT. Runs Aug-26 to Mar-27 and then STOPS - their contracted book is empty from Apr-27 onward.
...

Sheet Case 2 - As Understood
B2: Case 2 - the case as we understand it - expanded: findings, corrections, and what they do to the returns
B3: Same skeleton as Case 1. RED = our additions and corrections, each with its rationale. Staging follows the management discussion of 04-08-2026. EUR m unless marked.
B5: STAGES ON THE TIMELINE AS WE UNDERSTAND IT
C6: 2026 H2 | D6: 2027 | E6: 2028 | F6: 2029
C7: Framework year (partner tests) | D7: Top-up round + commercial agreements from Oct-27 | E7: Certified utility entry | F7: Approach to profitability - exit window
B9: A. OUR FINDINGS - THE FIVE GAPS BETWEEN THE STORY AND THE PAPER
B10: 1. No certification budget anywhere in the use of funds | J10: Case 1, sections B and D: the NA-utilities and OEM segments assume certified sales, yet not one euro of KTW/DVGW/NSF money appears in their costs. The utility track AND the exit multiple depend on starting now. We add the EUR 2.2m programme in section D below.
B11: 2. Frameworks are 12-month tests, not volume | J11: Partner frameworks effective c.Oct-26 are tests; volume and price commitments only from c.Oct-27. That strains 'profitable in 18-24 months' and makes a 2027 top-up likely - management half-conceded both on the call. We model the top-up in section F.
B12: 3. AFFF is project revenue in a closing window | J12: The 2030 EU foam-replacement deadline caps Track 1. The recurring story that justifies EUR 15m pre-money is the utility track - which is certification-gated (finding 1). Our revenue build in section C keeps the tracks separate so this is visible.
B13: 4. Destruction-only disposal for POP-loaded resin | J13: AFFF-loaded resin above POP thresholds may not be regenerated - it must be destroyed. Their REGEN product line (Case 1, section B) has no revenue attached in the Base case, rightly; a destruction contract must be priced before volumes start. Contracting cost sits in section D.
B14: 5. The historic preference stack is real | J14: MIG on the call: 'we did a lot of down rounds - we want our money'. The deck says new money is unaffected; the term sheet PRESERVES historic preferences (order EUR 12m). If they rank ahead at mid exits, converting holders lose c.40% of pro-rata proceeds - worth c.EUR 1m to us. See the waterfall memo in section H.
B16: B. WHAT WE CHANGE VS THEIR MODEL (RED = OUR ASSUMPTION)
B17: Revenue: their four layers replaced by the three tracks | C17: see C | J17: Management's own strategy (04-08-2026): Track 1 AFFF partner channel, Track 2 certification-gated utilities, Track 3 integrators/bulk - Track 3 excluded from the base as 'not tangible enough' (their words), despite the Solenis US agreement in finalisation.
B18: Cost of sales | C18: 0.4 | J18: 60% gross margin early vs their c.72% at scale - partner-channel discounts and small batches.
B19: Running costs kept at c.90% of their plan | C19: 0.9 | J19: Costs never fall as fast as revenue slips - benchmark evidence (Pyrum delivered 55-58% of guidance with signed customers).
B20: Working capital introduced | C20: 0.15 | J20: 15% of revenue - resin inventory and partner receivables, absent from their plan entirely (Case 1, section F).
B21: Certification + disposal programme added | C21: see D | J21: EUR 2.2m across 2026-29, itemised below - the money finding 1 says is missing.
B22: EUR 5m top-up round, 2027 | C22: 5 | J22: At an assumed EUR 20m pre-money after Track-1 proof; dilutes all pre-top-up holders x0.8. Finding 2.
B23: Exit multiple unchanged | C23: 5 | J23: Same 5.0x revenue as Case 1 - arguably earned by then (certified product + commercial agreements) but on lower revenue.
B25: C. REVENUE - THE THREE TRACKS AS MANAGEMENT DESCRIBED THEM (EUR m)
B26: EUR m | C26: 2026 H2 | D26: 2027 | E26: 2028 | F26: 2029 | J26: Notes
B27: Track 1 - AFFF partner channel | C27: 0.3 | D27: 0.9 | E27: 2.6 | F27: 4.5 | J27: Cornelsen (DE), AquaCorp (AUS), Amazon Filters (UK) - frameworks expected signed within weeks, effective c.Oct-26; 12-month tests, volume/price agreements from c.Oct-27; partners buy for stock. Scales into the 2030 replacement wave. CEO himself reset 2026 to EUR 0.25-0.35m.
B28: Track 2 - water utilities (certification-gated) | C28: 0 | D28: 0 | E28: 0.4 | F28: 1.5 | J28: First certified sales 2028 - the benchmark says 12-24 months per market; management's Q1/Q2-27 is the optimistic end. This is the recurring story behind the EUR 15m pre.
B29: Track 3 - integrators / bulk resin (excluded) | C29: 0 | D29: 0 | E29: 0 | F29: 0 | J29: Upside, not plan - management's own words; Solenis US agreement in finalisation. Becomes real after Track 1 proves volume manufacturing; revisit at the 2027 round.
B30: Total revenue | C30: =SUM(C27:C29) -> 0.3 | D30: =SUM(D27:D29) -> 0.9 | E30: =SUM(E27:E29) -> 3 | F30: =SUM(F27:F29) -> 6
B31: memo: their plan total (Case 1) | C31: ='Case 1 - As Given'!C65 -> 0.21 | D31: ='Case 1 - As Given'!D65 -> 2.17 | E31: ='Case 1 - As Given'!E65 -> 6.86 | F31: ='Case 1 - As Given'!F65 -> 8.02 | J31: Their EUR 6.86m in 2028 vs our EUR 3.00m - the gap is almost entirely the unnamed top-down segments of Case 1, section D.
B32: memo: revenue we do not underwrite | C32: =C31-C30 -> -0.09 | D32: =D31-D30 -> 1.27 | E32: =E31-E30 -> 3.86 | F32: =F31-F30 -> 2.02
B34: D. THE CERTIFICATION + DISPOSAL PROGRAMME - ITEMISED (EUR m; RED = OUR ESTIMATE)
B35: EUR m | C35: 2026 H2 | D35: 2027 | E35: 2028 | F35: 2029 | J35: Notes
B36: Germany: KTW-BWGL + DVGW W270 (resin + filter) | C36: 0.15 | D36: 0.3 | E36: 0 | F36: 0 | J36: Without these no German utility may buy, however well it works. 12-18 months.
B37: EU drinking-water positive lists / migration testing | C37: 0.05 | D37: 0.15 | E37: 0.1 | F37: 0 | J37: EU framework binding from 2026; national rules still apply per country.
B38: US: NSF/ANSI 61 + 53 (resin + cartridge family) | C38: 0 | D38: 0.2 | E38: 0.2 | F38: 0 | J38: The US equivalent - Case 1's NA-utilities segment is impossible without it.
B39: UK (DWI Reg 31) + France (ACS) | C39: 0 | D39: 0.1 | E39: 0.1 | F39: 0.1 | J39: Two further markets in their plan.
B40: Independent performance testing (lifetime, real water) | C40: 0.1 | D40: 0.15 | E40: 0.1 | F40: 0 | J40: The data a bank's - or an acquirer's - technical adviser reads first.
B41: Annual audits, retests and fees | C41: 0 | D41: 0.05 | E41: 0.1 | F41: 0.096 | J41: Approvals are a programme, not a certificate; fees continue while the product sells.
B42: Destruction-route contracting for POP-loaded resin | C42: 0.1 | D42: 0.05 | E42: 0 | F42: 0 | J42: Waste profile + priced contract (rotary-kiln incinerators DE/BE/FR - Indaver, Seche, Veolia; gate fees c.USD 2,300-5,000/t). A contracting task, not research. Finding 4.
B43: Certification + disposal - total | C43: =SUM(C36:C42) -> 0.4 | D43: =SUM(D36:D42) -> 1 | E43: =SUM(E36:E42) -> 0.6 | F43: =SUM(F36:F42) -> 0.196 | J43: EUR 2.2m over the window - re-phased from the Programme workbook of 31-07 (its full estimate EUR 2.3m incl. rolling fees beyond 2029). Feeds the P&L below.
B45: E. P&L - THE SAME COMPANY UNDER OUR ASSUMPTIONS
B46: EUR m | C46: 2026 H2 | D46: 2027 | E46: 2028 | F46: 2029 | J46: Notes
B47: Total revenue | C47: =C30 -> 0.3 | D47: =D30 -> 0.9 | E47: =E30 -> 3 | F47: =F30 -> 6
...
